Workbook
Name csDesignMode: 1
Name Expense_codes: 'Expense Form Extra Rows'!$E$70:$G$76
Name Expense_codes: 'Expense Claim Form '!$E$72:$G$78
Name sub: 'Expense Claim Form '!$A$40
Name sub: 'Expense Form Extra Rows'!#REF!
Name sub: 'Mileage Detail'!#REF!
Name sub: 'Mileage Detail Extra Rows'!#REF!
Name sub: #REF!

Sheet Expense Claim Form 
A1: EXPENSES CLAIM FORM (Use for expenditure incurred from 1 December 2014)
A4: NAME | C4: Brian Fleming | E4: BUSINESS UNIT | I4: DEPT/SITE NAME | L4: FUEL TYPE | M4: ='Mileage Detail'!M4 -> DIESEL | N4: CLAIM DATE | O4: FINANCE USE ONLY
L5: ENGINE CC | M5: ='Mileage Detail'!M5 -> 1600
A6: STAFF NO | E6: Taylor Wimpey West of Scotland | L6: VEHICLE REG. | M6: ='Mileage Detail'!M6 -> SB65 XCW | N6: =TODAY() -> 46043
A8: EXPENSE CODE | B8: DATE | C8: FULL DETAILS OF EXPENSE (including details of location/site/office visited, reason for travel by means other than by car; details of items purchased; reasons for entertainment & guests' names and employers) | E8: VAT CODE | F8: RECEIPT ATTACHED | G8: TOTAL AMOUNT CLAIMED | H8: VAT (see notes) | I8: SUBSISTENCE (see notes) | J8: TRAVEL (see notes) | K8: BUSINESS ENTERTAINMENT (inc VAT) (see notes) | L8: STAFF ENTERTAINMENT (ex VAT) (see notes) | M8: PROF SUBS (see notes) | N8: OTHER EXPENSES (see notes) | O8: PSA ITEM
C11: Expense Detail | D11: Reason for Expense | F11: Yes/No | G11: £ | H11: £ | I11: £ | J11: £ | K11: £ | L11: £ | M11: £ | N11: £ | O11: Yes/No
G12: 0 | H12: =IF($E12=B$74,ROUND((G12*(1/6)),2),0) -> 0 | I12: =IF($A12="s",ROUND((+$G12-$H12),2),0) -> 0 | J12: =IF($A12="t",ROUND((+$G12-$H12),2),0) -> 0 | K12: =IF($A12="e",ROUND((+$G12-$H12),2),0) -> 0 | L12: =IF($A12="es",ROUND((+$G12-$H12),2),0) -> 0 | M12: =IF($A12="pf",ROUND((+$G12-$H12),2),0) -> 0 | N12: =IF($A12="o",ROUND((+$G12-$H12),2),0) -> 0
G13: 0 | H13: =IF($E13=B$74,ROUND((G13*(1/6)),2),0) -> 0 | I13: =IF($A13="s",ROUND((+$G13-$H13),2),0) -> 0 | J13: =IF($A13="t",ROUND((+$G13-$H13),2),0) -> 0 | K13: =IF($A13="e",ROUND((+$G13-$H13),2),0) -> 0 | L13: =IF($A13="es",ROUND((+$G13-$H13),2),0) -> 0 | M13: =IF($A13="pf",ROUND((+$G13-$H13),2),0) -> 0 | N13: =IF($A13="o",ROUND((+$G13-$H13),2),0) -> 0
G14: 0 | H14: =IF($E14=B$74,ROUND((G14*(1/6)),2),0) -> 0 | I14: =IF($A14="s",ROUND((+$G14-$H14),2),0) -> 0 | J14: =IF($A14="t",ROUND((+$G14-$H14),2),0) -> 0 | K14: =IF($A14="e",ROUND((+$G14-$H14),2),0) -> 0 | L14: =IF($A14="es",ROUND((+$G14-$H14),2),0) -> 0 | M14: =IF($A14="pf",ROUND((+$G14-$H14),2),0) -> 0 | N14: =IF($A14="o",ROUND((+$G14-$H14),2),0) -> 0
G15: 0 | H15: =IF($E15=B$74,ROUND((G15*(1/6)),2),0) -> 0 | I15: =IF($A15="s",ROUND((+$G15-$H15),2),0) -> 0 | J15: =IF($A15="t",ROUND((+$G15-$H15),2),0) -> 0 | K15: =IF($A15="e",ROUND((+$G15-$H15),2),0) -> 0 | L15: =IF($A15="es",ROUND((+$G15-$H15),2),0) -> 0 | M15: =IF($A15="pf",ROUND((+$G15-$H15),2),0) -> 0 | N15: =IF($A15="o",ROUND((+$G15-$H15),2),0) -> 0
G16: 0 | H16: =IF($E16=B$74,ROUND((G16*(1/6)),2),0) -> 0 | I16: =IF($A16="s",ROUND((+$G16-$H16),2),0) -> 0 | J16: =IF($A16="t",ROUND((+$G16-$H16),2),0) -> 0 | K16: =IF($A16="e",ROUND((+$G16-$H16),2),0) -> 0 | L16: =IF($A16="es",ROUND((+$G16-$H16),2),0) -> 0 | M16: =IF($A16="pf",ROUND((+$G16-$H16),2),0) -> 0 | N16: =IF($A16="o",ROUND((+$G16-$H16),2),0) -> 0
G17: 0 | H17: =IF($E17=B$74,ROUND((G17*(1/6)),2),0) -> 0 | I17: =IF($A17="s",ROUND((+$G17-$H17),2),0) -> 0 | J17: =IF($A17="t",ROUND((+$G17-$H17),2),0) -> 0 | K17: =IF($A17="e",ROUND((+$G17-$H17),2),0) -> 0 | L17: =IF($A17="es",ROUND((+$G17-$H17),2),0) -> 0 | M17: =IF($A17="pf",ROUND((+$G17-$H17),2),0) -> 0 | N17: =IF($A17="o",ROUND((+$G17-$H17),2),0) -> 0
G18: 0 | H18: =IF($E18=B$74,ROUND((G18*(1/6)),2),0) -> 0 | I18: =IF($A18="s",ROUND((+$G18-$H18),2),0) -> 0 | J18: =IF($A18="t",ROUND((+$G18-$H18),2),0) -> 0 | K18: =IF($A18="e",ROUND((+$G18-$H18),2),0) -> 0 | L18: =IF($A18="es",ROUND((+$G18-$H18),2),0) -> 0 | M18: =IF($A18="pf",ROUND((+$G18-$H18),2),0) -> 0 | N18: =IF($A18="o",ROUND((+$G18-$H18),2),0) -> 0
G19: 0 | H19: =IF($E19=B$74,ROUND((G19*(1/6)),2),0) -> 0 | I19: =IF($A19="s",ROUND((+$G19-$H19),2),0) -> 0 | J19: =IF($A19="t",ROUND((+$G19-$H19),2),0) -> 0 | K19: =IF($A19="e",ROUND((+$G19-$H19),2),0) -> 0 | L19: =IF($A19="es",ROUND((+$G19-$H19),2),0) -> 0 | M19: =IF($A19="pf",ROUND((+$G19-$H19),2),0) -> 0 | N19: =IF($A19="o",ROUND((+$G19-$H19),2),0) -> 0
G20: 0 | H20: =IF($E20=B$74,ROUND((G20*(1/6)),2),0) -> 0 | I20: =IF($A20="s",ROUND((+$G20-$H20),2),0) -> 0 | J20: =IF($A20="t",ROUND((+$G20-$H20),2),0) -> 0 | K20: =IF($A20="e",ROUND((+$G20-$H20),2),0) -> 0 | L20: =IF($A20="es",ROUND((+$G20-$H20),2),0) -> 0 | M20: =IF($A20="pf",ROUND((+$G20-$H20),2),0) -> 0 | N20: =IF($A20="o",ROUND((+$G20-$H20),2),0) -> 0
G21: 0 | H21: =IF($E21=B$74,ROUND((G21*(1/6)),2),0) -> 0 | I21: =IF($A21="s",ROUND((+$G21-$H21),2),0) -> 0 | J21: =IF($A21="t",ROUND((+$G21-$H21),2),0) -> 0 | K21: =IF($A21="e",ROUND((+$G21-$H21),2),0) -> 0 | L21: =IF($A21="es",ROUND((+$G21-$H21),2),0) -> 0 | M21: =IF($A21="pf",ROUND((+$G21-$H21),2),0) -> 0 | N21: =IF($A21="o",ROUND((+$G21-$H21),2),0) -> 0
G22: 0 | H22: =IF($E22=B$74,ROUND((G22*(1/6)),2),0) -> 0 | I22: =IF($A22="s",ROUND((+$G22-$H22),2),0) -> 0 | J22: =IF($A22="t",ROUND((+$G22-$H22),2),0) -> 0 | K22: =IF($A22="e",ROUND((+$G22-$H22),2),0) -> 0 | L22: =IF($A22="es",ROUND((+$G22-$H22),2),0) -> 0 | M22: =IF($A22="pf",ROUND((+$G22-$H22),2),0) -> 0 | N22: =IF($A22="o",ROUND((+$G22-$H22),2),0) -> 0
G23: 0 | H23: =IF($E23=B$74,ROUND((G23*(1/6)),2),0) -> 0 | I23: =IF($A23="s",ROUND((+$G23-$H23),2),0) -> 0 | J23: =IF($A23="t",ROUND((+$G23-$H23),2),0) -> 0 | K23: =IF($A23="e",ROUND((+$G23-$H23),2),0) -> 0 | L23: =IF($A23="es",ROUND((+$G23-$H23),2),0) -> 0 | M23: =IF($A23="pf",ROUND((+$G23-$H23),2),0) -> 0 | N23: =IF($A23="o",ROUND((+$G23-$H23),2),0) -> 0
... G36: 0 | H36: =IF($E36=B$74,ROUND((G36*(1/6)),2),0) -> 0 | I36: =IF($A36="s",ROUND((+$G36-$H36),2),0) -> 0 | J36: =IF($A36="t",ROUND((+$G36-$H36),2),0) -> 0 | K36: =IF($A36="e",ROUND((+$G36-$H36),2),0) -> 0 | L36: =IF($A36="es",ROUND((+$G36-$H36),2),0) -> 0 | M36: =IF($A36="pf",ROUND((+$G36-$H36),2),0) -> 0 | N36: =IF($A36="o",ROUND((+$G36-$H36),2),0) -> 0
A37: T | C37: Mileage converted to monetary amount | E37: =IF(B49="yes","P98",IF(B53=0.45,"P99","P10")) -> P99 | G37: =B54 -> 0 | H37: =IF($E37=B74,ROUND((G37*(1/6)),2),IF($E37=B75,ROUND(B54-(B54/1.05882),2),IF($E37=B76,ROUND(B54-(B54/1.11111),2),0))) -> 0 | I37: =IF($A37="s",ROUND((+$G37-$H37),2),0) -> 0 | J37: =IF($A37="t",ROUND((+$G37-$H37),2),0) -> 0 | K37: =IF($A37="e",ROUND((+$G37-$H37),2),0) -> 0 | L37: =IF($A37="es",ROUND((+$G37-$H37),2),0) -> 0 | M37: =IF($A37="pf",ROUND((+$G37-$H37),2),0) -> 0 | N37: =IF($A37="o",ROUND((+$G37-$H37),2),0) -> 0
A38: T | C38: Passenger mileage converted to monetary amount (will always be P10) | E38: P10 | G38: ='Mileage Detail'!J37 -> 0 | H38: =IF($E38=B74,ROUND((G38*(1/6)),2),0) -> 0 | I38: =IF($A38="s",ROUND((+$G38-$H38),2),0) -> 0 | J38: =IF($A38="t",ROUND((+$G38-$H38),2),0) -> 0 | K38: =IF($A38="e",ROUND((+$G38-$H38),2),0) -> 0 | L38: =IF($A38="es",ROUND((+$G38-$H38),2),0) -> 0 | M38: =IF($A38="pf",ROUND((+$G38-$H38),2),0) -> 0 | N38: =IF($A38="o",ROUND((+$G38-$H38),2),0) -> 0
C40: Brought forward from Extra Rows sheet | G40: ='Expense Form Extra Rows'!G52 -> 0 | H40: ='Expense Form Extra Rows'!H52 -> 0 | I40: ='Expense Form Extra Rows'!I52 -> 0 | J40: ='Expense Form Extra Rows'!J52 -> 0 | K40: ='Expense Form Extra Rows'!K52 -> 0 | L40: ='Expense Form Extra Rows'!L52 -> 0 | M40: ='Expense Form Extra Rows'!M52 -> 0 | N40: ='Expense Form Extra Rows'!N52 -> 0
H41: =IF($E41=B74,ROUND((G41*(1/6)),2),0) -> 0 | I41: =IF($A41="s",ROUND((+$G41-$H41),2),0) -> 0 | J41: =IF($A41="t",ROUND((+$G41-$H41),2),0) -> 0 | K41: =IF($A41="e",ROUND((+$G41-$H41),2),0) -> 0 | L41: =IF($A41="es",ROUND((+$G41-$H41),2),0) -> 0 | M41: =IF($A41="pf",ROUND((+$G41-$H41),2),0) -> 0 | N41: =IF($A41="o",ROUND((+$G41-$H41),2),0) -> 0
E42: TOTAL AMOUNT OF EXPENSES CLAIMED £ | G42: =ROUND(SUM(G12:G41),2) -> 0 | H42: =ROUND(SUM(H12:H41),2) -> 0 | I42: =ROUND(SUM(I12:I41),2) -> 0 | J42: =ROUND(SUM(J12:J41),2) -> 0 | K42: =ROUND(SUM(K12:K41),2) -> 0 | L42: =ROUND(SUM(L12:L41),2) -> 0 | M42: =ROUND(SUM(M12:M41),2) -> 0 | N42: =ROUND(SUM(N12:N41),2) -> 0
G43: ALLOCATION CODES | L43: VARIOUS
B44: =IF(OR(B49="no",AND(B49="yes",B54=0.25)),0,"WARNING - NON COMPANY CAR USERS WHO HAVE CLAIMED OVER 10,000 BUSINESS MILES IN A TAX YEAR MUST USE A CLAIM PER MILE RATE OF 25p") -> 0 | G44: NET AMOUNT | H44: OFFICE | I44: 95285 | J44: 95265 | K44: 95143 | L44: 95141 | M44: 95185 | N44: 95195 | O44: VAT Net Amounts
G45: =+G42-H42-SUM(I56,J56,K58,L56,M56,N56) -> 0 | H45: SALES | I45: 91285 | J45: 91235 | N45: 91265 / 91285
A47: Mileage brought forward from Mileage Detail sheets: | H47: SITE | I47: 16185 | J47: 16185 | K47: 16185 | L47: 16185 | M47: 16185 | N47: 16185
A49: Over 10,000 miles | B49: NO | C49: Select "YES" only if you have claimed over 10,000 business miles in a tax year AND you don’t have a company car or car allowance. Otherwise leave as "NO". | G49: (Office Use Only) | H49: P10 | I49: =SUMIF($E$12:$E$39,"=P10",I$12:I$39)+'Expense Form Extra Rows'!I59 -> 0 | J49: =SUMIF($E$12:$E$39,"=P10",J$12:J$39)+'Expense Form Extra Rows'!J59 -> 0 | K49: P61 | L49: =SUMIF($E$12:$E$39,"=P10",L$12:L$39)+'Expense Form Extra Rows'!L59 -> 0 | M49: =SUMIF($E$12:$E$39,"=P10",M$12:M$39)+'Expense Form Extra Rows'!M59 -> 0 | N49: =SUMIF($E$12:$E$39,"=P10",N$12:N$39)+'Expense Form Extra Rows'!N59 -> 0 | O49: =SUM(I49:N49) -> 0
A51: Number of Miles | B51: ='Mileage Detail'!E37 -> 0 | C51: Please enter appropriate mileage rate based on type of vehicle. Company car drivers/car allowance recipients should refer to HMRC advisory rates (see below for link). Non company car drivers should refer to rates on the Mileage Claim Guide tab. | G51: VAT CODE ANALYSIS | H51: P99 | J51: =SUMIF($E$12:$E$39,"=P99",J$12:J$39)+'Expense Form Extra Rows'!J61 -> 0 | O51: =SUM(I51:N51) -> 0
H52: P98 | J52: =SUMIF($E$12:$E$39,"=P98",J$12:J$39)+'Expense Form Extra Rows'!J62 -> 0 | O52: =SUM(I52:N52) -> 0
A53: £0.xx rate per mile | B53: 0.45 | H53: P30 | I53: =SUMIF($E$12:$E$39,"=P30",I$12:I$39)+'Expense Form Extra Rows'!I63 -> 0 | J53: =SUMIF($E$12:$E$39,"=P30",J$12:J$39)+'Expense Form Extra Rows'!J63 -> 0 | L53: =SUMIF($E$12:$E$39,"=P30",L$12:L$39)+'Expense Form Extra Rows'!L63 -> 0 | M53: =SUMIF($E$12:$E$39,"=P30",M$12:M$39)+'Expense Form Extra Rows'!M63 -> 0 | N53: =SUMIF($E$12:$E$39,"=P30",N$12:N$39)+'Expense Form Extra Rows'!N63 -> 0 | O53: =SUM(I53:N53) -> 0
A54: Total claim | B54: =B51*B53 -> 0 | C54: https://www.gov.uk/government/publications/advisory-fuel-rates/current-rates | H54: P01 | I54: =SUMIF($E$12:$E$39,"=P01",I$12:I$39)+'Expense Form Extra Rows'!I64 -> 0 | J54: =SUMIF($E$12:$E$39,"=P01",J$12:J$39)+'Expense Form Extra Rows'!J64 -> 0 | L54: =SUMIF($E$12:$E$39,"=P01",L$12:L$39)+'Expense Form Extra Rows'!L64 -> 0 | M54: =SUMIF($E$12:$E$39,"=P01",M$12:M$39)+'Expense Form Extra Rows'!M64 -> 0 | N54: =SUMIF($E$12:$E$39,"=P01",N$12:N$39)+'Expense Form Extra Rows'!N64 -> 0 | O54: =SUM(I54:N54) -> 0
H55: P32 | I55: =SUMIF($E$12:$E$39,"=P32",I$12:I$39)+'Expense Form Extra Rows'!I65 -> 0 | J55: =SUMIF($E$12:$E$39,"=P32",J$12:J$39)+'Expense Form Extra Rows'!J65 -> 0 | L55: =SUMIF($E$12:$E$39,"=P32",L$12:L$39)+'Expense Form Extra Rows'!L65 -> 0 | M55: =SUMIF($E$12:$E$39,"=P32",M$12:M$39)+'Expense Form Extra Rows'!M65 -> 0 | N55: =SUMIF($E$12:$E$39,"=P32",N$12:N$39)+'Expense Form Extra Rows'!N65 -> 0 | O55: =SUM(I55:N55) -> 0
H56: P61 | I56: =SUMIF($E$12:$E$39,"=P61",I$12:I$39)+'Expense Form Extra Rows'!I66 -> 0 | J56: =SUMIF($E$12:$E$39,"=P61",J$12:J$39)+'Expense Form Extra Rows'!J66 -> 0 | K56: =K42-K58 -> 0 | L56: =SUMIF($E$12:$E$39,"=P61",L$12:L$39)+'Expense Form Extra Rows'!L66 -> 0 | M56: =SUMIF($E$12:$E$39,"=P61",M$12:M$39)+'Expense Form Extra Rows'!M66 -> 0 | N56: =SUMIF($E$12:$E$39,"=P61",N$12:N$39)+'Expense Form Extra Rows'!N66 -> 0 | O56: =SUM(I56:N56) -> 0
H57: TOTAL | I57: =SUM(I49:I56) -> 0 | J57: =SUM(J49:J56) -> 0 | K57: =SUM(K49:K56) -> 0 | L57: =SUM(L49:L56) -> 0 | M57: =SUM(M49:M56) -> 0 | N57: =SUM(N49:N56) -> 0
K58: =((SUMIF($E$12:$E$39,"=P61",K$12:K$39))*20/120)+'Expense Form Extra Rows'!K68 -> 0
B60: FOR OFFICE USE ONLY
G61: I certify this is a correct statement of expense incurred by me wholly and necessarily on company business | N61: Authorisation is in line with the Business Unit's delegated authorities
C63: Processed by Finance | H63: SIGNED | L63: DATE
...

Sheet Expense Form Extra Rows
A1: EXPENSES CLAIM FORM (Use for expenditure incurred from 1 December 2014)
A4: NAME | C4: ='Expense Claim Form '!C4:D5 -> Brian Fleming | E4: BUSINESS UNIT | I4: DEPT/SITE NAME | L4: FUEL TYPE | M4: ='Mileage Detail'!M4 -> DIESEL | N4: CLAIM DATE | O4: FINANCE USE ONLY
L5: ENGINE CC | M5: ='Mileage Detail'!M5 -> 1600
A6: STAFF NO | C6: ='Expense Claim Form '!C6:D7 -> 0 | E6: ='Expense Claim Form '!E6:H7 -> Taylor Wimpey West of Scotland | I6: ='Expense Claim Form '!I6:K7 -> 0 | L6: VEHICLE REG. | M6: ='Mileage Detail'!M6 -> SB65 XCW | N6: =TODAY() -> 46043
A8: EXPENSE CODE | B8: DATE | C8: FULL DETAILS OF EXPENSE (including details of location/site/office visited, reason for travel by means other than by car; details of items purchased; reasons for entertainment & guests' names and employers) | E8: VAT CODE | F8: RECEIPT ATTACHED | G8: TOTAL AMOUNT CLAIMED | H8: VAT (see notes) | I8: SUBSISTENCE (see notes) | J8: TRAVEL (see notes) | K8: BUSINESS ENTERTAINMENT (inc VAT) (see notes) | L8: STAFF ENTERTAINMENT (ex VAT) (see notes) | M8: PROF SUBS (see notes) | N8: OTHER EXPENSES (see notes) | O8: PSA ITEM
C11: Expense Detail | D11: Reason for Expense | F11: Yes/No | G11: £ | H11: £ | I11: £ | J11: £ | K11: £ | L11: £ | M11: £ | N11: £ | O11: Yes/No
H12: =IF($E12=B$72,ROUND((G12*(1/6)),2),0) -> 0 | I12: =IF($A12="s",ROUND((+$G12-$H12),2),0) -> 0 | J12: =IF($A12="t",ROUND((+$G12-$H12),2),0) -> 0 | K12: =IF($A12="e",ROUND((+$G12-$H12),2),0) -> 0 | L12: =IF($A12="es",ROUND((+$G12-$H12),2),0) -> 0 | M12: =IF($A12="pf",ROUND((+$G12-$H12),2),0) -> 0 | N12: =IF($A12="o",ROUND((+$G12-$H12),2),0) -> 0
H13: =IF($E13=B$72,ROUND((G13*(1/6)),2),0) -> 0 | I13: =IF($A13="s",ROUND((+$G13-$H13),2),0) -> 0 | J13: =IF($A13="t",ROUND((+$G13-$H13),2),0) -> 0 | K13: =IF($A13="e",ROUND((+$G13-$H13),2),0) -> 0 | L13: =IF($A13="es",ROUND((+$G13-$H13),2),0) -> 0 | M13: =IF($A13="pf",ROUND((+$G13-$H13),2),0) -> 0 | N13: =IF($A13="o",ROUND((+$G13-$H13),2),0) -> 0
H14: =IF($E14=B$72,ROUND((G14*(1/6)),2),0) -> 0 | I14: =IF($A14="s",ROUND((+$G14-$H14),2),0) -> 0 | J14: =IF($A14="t",ROUND((+$G14-$H14),2),0) -> 0 | K14: =IF($A14="e",ROUND((+$G14-$H14),2),0) -> 0 | L14: =IF($A14="es",ROUND((+$G14-$H14),2),0) -> 0 | M14: =IF($A14="pf",ROUND((+$G14-$H14),2),0) -> 0 | N14: =IF($A14="o",ROUND((+$G14-$H14),2),0) -> 0
H15: =IF($E15=B$72,ROUND((G15*(1/6)),2),0) -> 0 | I15: =IF($A15="s",ROUND((+$G15-$H15),2),0) -> 0 | J15: =IF($A15="t",ROUND((+$G15-$H15),2),0) -> 0 | K15: =IF($A15="e",ROUND((+$G15-$H15),2),0) -> 0 | L15: =IF($A15="es",ROUND((+$G15-$H15),2),0) -> 0 | M15: =IF($A15="pf",ROUND((+$G15-$H15),2),0) -> 0 | N15: =IF($A15="o",ROUND((+$G15-$H15),2),0) -> 0
H16: =IF($E16=B$72,ROUND((G16*(1/6)),2),0) -> 0 | I16: =IF($A16="s",ROUND((+$G16-$H16),2),0) -> 0 | J16: =IF($A16="t",ROUND((+$G16-$H16),2),0) -> 0 | K16: =IF($A16="e",ROUND((+$G16-$H16),2),0) -> 0 | L16: =IF($A16="es",ROUND((+$G16-$H16),2),0) -> 0 | M16: =IF($A16="pf",ROUND((+$G16-$H16),2),0) -> 0 | N16: =IF($A16="o",ROUND((+$G16-$H16),2),0) -> 0
H17: =IF($E17=B$72,ROUND((G17*(1/6)),2),0) -> 0 | I17: =IF($A17="s",ROUND((+$G17-$H17),2),0) -> 0 | J17: =IF($A17="t",ROUND((+$G17-$H17),2),0) -> 0 | K17: =IF($A17="e",ROUND((+$G17-$H17),2),0) -> 0 | L17: =IF($A17="es",ROUND((+$G17-$H17),2),0) -> 0 | M17: =IF($A17="pf",ROUND((+$G17-$H17),2),0) -> 0 | N17: =IF($A17="o",ROUND((+$G17-$H17),2),0) -> 0
H18: =IF($E18=B$72,ROUND((G18*(1/6)),2),0) -> 0 | I18: =IF($A18="s",ROUND((+$G18-$H18),2),0) -> 0 | J18: =IF($A18="t",ROUND((+$G18-$H18),2),0) -> 0 | K18: =IF($A18="e",ROUND((+$G18-$H18),2),0) -> 0 | L18: =IF($A18="es",ROUND((+$G18-$H18),2),0) -> 0 | M18: =IF($A18="pf",ROUND((+$G18-$H18),2),0) -> 0 | N18: =IF($A18="o",ROUND((+$G18-$H18),2),0) -> 0
H19: =IF($E19=B$72,ROUND((G19*(1/6)),2),0) -> 0 | I19: =IF($A19="s",ROUND((+$G19-$H19),2),0) -> 0 | J19: =IF($A19="t",ROUND((+$G19-$H19),2),0) -> 0 | K19: =IF($A19="e",ROUND((+$G19-$H19),2),0) -> 0 | L19: =IF($A19="es",ROUND((+$G19-$H19),2),0) -> 0 | M19: =IF($A19="pf",ROUND((+$G19-$H19),2),0) -> 0 | N19: =IF($A19="o",ROUND((+$G19-$H19),2),0) -> 0
H20: =IF($E20=B$72,ROUND((G20*(1/6)),2),0) -> 0 | I20: =IF($A20="s",ROUND((+$G20-$H20),2),0) -> 0 | J20: =IF($A20="t",ROUND((+$G20-$H20),2),0) -> 0 | K20: =IF($A20="e",ROUND((+$G20-$H20),2),0) -> 0 | L20: =IF($A20="es",ROUND((+$G20-$H20),2),0) -> 0 | M20: =IF($A20="pf",ROUND((+$G20-$H20),2),0) -> 0 | N20: =IF($A20="o",ROUND((+$G20-$H20),2),0) -> 0
H21: =IF($E21=B$72,ROUND((G21*(1/6)),2),0) -> 0 | I21: =IF($A21="s",ROUND((+$G21-$H21),2),0) -> 0 | J21: =IF($A21="t",ROUND((+$G21-$H21),2),0) -> 0 | K21: =IF($A21="e",ROUND((+$G21-$H21),2),0) -> 0 | L21: =IF($A21="es",ROUND((+$G21-$H21),2),0) -> 0 | M21: =IF($A21="pf",ROUND((+$G21-$H21),2),0) -> 0 | N21: =IF($A21="o",ROUND((+$G21-$H21),2),0) -> 0
H22: =IF($E22=B$72,ROUND((G22*(1/6)),2),0) -> 0 | I22: =IF($A22="s",ROUND((+$G22-$H22),2),0) -> 0 | J22: =IF($A22="t",ROUND((+$G22-$H22),2),0) -> 0 | K22: =IF($A22="e",ROUND((+$G22-$H22),2),0) -> 0 | L22: =IF($A22="es",ROUND((+$G22-$H22),2),0) -> 0 | M22: =IF($A22="pf",ROUND((+$G22-$H22),2),0) -> 0 | N22: =IF($A22="o",ROUND((+$G22-$H22),2),0) -> 0
H23: =IF($E23=B$72,ROUND((G23*(1/6)),2),0) -> 0 | I23: =IF($A23="s",ROUND((+$G23-$H23),2),0) -> 0 | J23: =IF($A23="t",ROUND((+$G23-$H23),2),0) -> 0 | K23: =IF($A23="e",ROUND((+$G23-$H23),2),0) -> 0 | L23: =IF($A23="es",ROUND((+$G23-$H23),2),0) -> 0 | M23: =IF($A23="pf",ROUND((+$G23-$H23),2),0) -> 0 | N23: =IF($A23="o",ROUND((+$G23-$H23),2),0) -> 0
... H41: =IF($E41=B$72,ROUND((G41*(1/6)),2),0) -> 0 | I41: =IF($A41="s",ROUND((+$G41-$H41),2),0) -> 0 | J41: =IF($A41="t",ROUND((+$G41-$H41),2),0) -> 0 | K41: =IF($A41="e",ROUND((+$G41-$H41),2),0) -> 0 | L41: =IF($A41="es",ROUND((+$G41-$H41),2),0) -> 0 | M41: =IF($A41="pf",ROUND((+$G41-$H41),2),0) -> 0 | N41: =IF($A41="o",ROUND((+$G41-$H41),2),0) -> 0
G42: 0 | H42: =IF($E42=B$72,ROUND((G42*(1/6)),2),0) -> 0 | I42: =IF($A42="s",ROUND((+$G42-$H42),2),0) -> 0 | J42: =IF($A42="t",ROUND((+$G42-$H42),2),0) -> 0 | K42: =IF($A42="e",ROUND((+$G42-$H42),2),0) -> 0 | L42: =IF($A42="es",ROUND((+$G42-$H42),2),0) -> 0 | M42: =IF($A42="pf",ROUND((+$G42-$H42),2),0) -> 0 | N42: =IF($A42="o",ROUND((+$G42-$H42),2),0) -> 0
G43: 0 | H43: =IF($E43=B$72,ROUND((G43*(1/6)),2),0) -> 0 | I43: =IF($A43="s",ROUND((+$G43-$H43),2),0) -> 0 | J43: =IF($A43="t",ROUND((+$G43-$H43),2),0) -> 0 | K43: =IF($A43="e",ROUND((+$G43-$H43),2),0) -> 0 | L43: =IF($A43="es",ROUND((+$G43-$H43),2),0) -> 0 | M43: =IF($A43="pf",ROUND((+$G43-$H43),2),0) -> 0 | N43: =IF($A43="o",ROUND((+$G43-$H43),2),0) -> 0
G44: 0 | H44: =IF($E44=B$72,ROUND((G44*(1/6)),2),0) -> 0 | I44: =IF($A44="s",ROUND((+$G44-$H44),2),0) -> 0 | J44: =IF($A44="t",ROUND((+$G44-$H44),2),0) -> 0 | K44: =IF($A44="e",ROUND((+$G44-$H44),2),0) -> 0 | L44: =IF($A44="es",ROUND((+$G44-$H44),2),0) -> 0 | M44: =IF($A44="pf",ROUND((+$G44-$H44),2),0) -> 0 | N44: =IF($A44="o",ROUND((+$G44-$H44),2),0) -> 0
G45: 0 | H45: =IF($E45=B$72,ROUND((G45*(1/6)),2),0) -> 0 | I45: =IF($A45="s",ROUND((+$G45-$H45),2),0) -> 0 | J45: =IF($A45="t",ROUND((+$G45-$H45),2),0) -> 0 | K45: =IF($A45="e",ROUND((+$G45-$H45),2),0) -> 0 | L45: =IF($A45="es",ROUND((+$G45-$H45),2),0) -> 0 | M45: =IF($A45="pf",ROUND((+$G45-$H45),2),0) -> 0 | N45: =IF($A45="o",ROUND((+$G45-$H45),2),0) -> 0
G46: 0 | H46: =IF($E46=B$72,ROUND((G46*(1/6)),2),0) -> 0 | I46: =IF($A46="s",ROUND((+$G46-$H46),2),0) -> 0 | J46: =IF($A46="t",ROUND((+$G46-$H46),2),0) -> 0 | K46: =IF($A46="e",ROUND((+$G46-$H46),2),0) -> 0 | L46: =IF($A46="es",ROUND((+$G46-$H46),2),0) -> 0 | M46: =IF($A46="pf",ROUND((+$G46-$H46),2),0) -> 0 | N46: =IF($A46="o",ROUND((+$G46-$H46),2),0) -> 0
G47: 0 | H47: =IF($E47=B$72,ROUND((G47*(1/6)),2),0) -> 0 | I47: =IF($A47="s",ROUND((+$G47-$H47),2),0) -> 0 | J47: =IF($A47="t",ROUND((+$G47-$H47),2),0) -> 0 | K47: =IF($A47="e",ROUND((+$G47-$H47),2),0) -> 0 | L47: =IF($A47="es",ROUND((+$G47-$H47),2),0) -> 0 | M47: =IF($A47="pf",ROUND((+$G47-$H47),2),0) -> 0 | N47: =IF($A47="o",ROUND((+$G47-$H47),2),0) -> 0
G48: 0 | H48: =IF($E48=B$72,ROUND((G48*(1/6)),2),0) -> 0 | I48: =IF($A48="s",ROUND((+$G48-$H48),2),0) -> 0 | J48: =IF($A48="t",ROUND((+$G48-$H48),2),0) -> 0 | K48: =IF($A48="e",ROUND((+$G48-$H48),2),0) -> 0 | L48: =IF($A48="es",ROUND((+$G48-$H48),2),0) -> 0 | M48: =IF($A48="pf",ROUND((+$G48-$H48),2),0) -> 0 | N48: =IF($A48="o",ROUND((+$G48-$H48),2),0) -> 0
G49: 0 | H49: =IF($E49=B$72,ROUND((G49*(1/6)),2),0) -> 0 | I49: =IF($A49="s",ROUND((+$G49-$H49),2),0) -> 0 | J49: =IF($A49="t",ROUND((+$G49-$H49),2),0) -> 0 | K49: =IF($A49="e",ROUND((+$G49-$H49),2),0) -> 0 | L49: =IF($A49="es",ROUND((+$G49-$H49),2),0) -> 0 | M49: =IF($A49="pf",ROUND((+$G49-$H49),2),0) -> 0 | N49: =IF($A49="o",ROUND((+$G49-$H49),2),0) -> 0
G50: 0 | H50: =IF($E50=B$72,ROUND((G50*(1/6)),2),0) -> 0 | I50: =IF($A50="s",ROUND((+$G50-$H50),2),0) -> 0 | J50: =IF($A50="t",ROUND((+$G50-$H50),2),0) -> 0 | K50: =IF($A50="e",ROUND((+$G50-$H50),2),0) -> 0 | L50: =IF($A50="es",ROUND((+$G50-$H50),2),0) -> 0 | M50: =IF($A50="pf",ROUND((+$G50-$H50),2),0) -> 0 | N50: =IF($A50="o",ROUND((+$G50-$H50),2),0) -> 0
G51: 0 | H51: =IF($E51=B$72,ROUND((G51*(1/6)),2),0) -> 0 | I51: =IF($A51="s",ROUND((+$G51-$H51),2),0) -> 0 | J51: =IF($A51="t",ROUND((+$G51-$H51),2),0) -> 0 | K51: =IF($A51="e",ROUND((+$G51-$H51),2),0) -> 0 | L51: =IF($A51="es",ROUND((+$G51-$H51),2),0) -> 0 | M51: =IF($A51="pf",ROUND((+$G51-$H51),2),0) -> 0 | N51: =IF($A51="o",ROUND((+$G51-$H51),2),0) -> 0
E52: TOTAL AMOUNT OF EXPENSES CLAIMED £ | G52: =ROUND(SUM(G12:G51),2) -> 0 | H52: =ROUND(SUM(H12:H51),2) -> 0 | I52: =ROUND(SUM(I12:I51),2) -> 0 | J52: =ROUND(SUM(J12:J51),2) -> 0 | K52: =ROUND(SUM(K12:K51),2) -> 0 | L52: =ROUND(SUM(L12:L51),2) -> 0 | M52: =ROUND(SUM(M12:M51),2) -> 0 | N52: =ROUND(SUM(N12:N51),2) -> 0
G53: ALLOCATION CODES | L53: VARIOUS
G54: NET AMOUNT | H54: OFFICE | I54: 95285 | J54: 95265 | K54: 95143 | L54: 95141 | M54: 95185 | N54: 95195 | O54: VAT Net Amounts
G55: =+G52-H52-SUM(I66:N66) -> 0 | H55: SALES | I55: 91285 | J55: 91235 | N55: 91265 / 91285
H57: SITE | I57: 16185 | J57: 16185 | K57: 16185 | L57: 16185 | M57: 16185 | N57: 16185
G59: (Office Use Only) | H59: P10 | I59: =SUMIF($E$12:$E$51,"=P10",I$12:I$51) -> 0 | J59: =SUMIF($E$12:$E$51,"=P10",J$12:J$51) -> 0 | K59: P61 | L59: =SUMIF($E$12:$E$51,"=P10",L$12:L$51) -> 0 | M59: =SUMIF($E$12:$E$51,"=P10",M$12:M$51) -> 0 | N59: =SUMIF($E$12:$E$51,"=P10",N$12:N$51) -> 0 | O59: =SUM(I59:N59) -> 0
G61: VAT CODE ANALYSIS | H61: P99 | J61: =SUMIF($E$12:$E$51,"=P99",J$12:J$51) -> 0 | O61: =SUM(I61:N61) -> 0
H62: P98 | J62: =SUMIF($E$12:$E$51,"=P98",J$12:J$51) -> 0 | O62: =SUM(I62:N62) -> 0
H63: P30 | I63: =SUMIF($E$12:$E$51,"=P30",I$12:I$51) -> 0 | J63: =SUMIF($E$12:$E$51,"=P30",J$12:J$51) -> 0 | L63: =SUMIF($E$12:$E$51,"=P30",L$12:L$51) -> 0 | M63: =SUMIF($E$12:$E$51,"=P30",M$12:M$51) -> 0 | N63: =SUMIF($E$12:$E$51,"=P30",N$12:N$51) -> 0 | O63: =SUM(I63:N63) -> 0
H64: P01 | I64: =SUMIF($E$12:$E$51,"=P01",I$12:I$51) -> 0 | J64: =SUMIF($E$12:$E$51,"=P01",J$12:J$51) -> 0 | L64: =SUMIF($E$12:$E$51,"=P01",L$12:L$51) -> 0 | M64: =SUMIF($E$12:$E$51,"=P01",M$12:M$51) -> 0 | N64: =SUMIF($E$12:$E$51,"=P01",N$12:N$51) -> 0 | O64: =SUM(I64:N64) -> 0
H65: P32 | I65: =SUMIF($E$12:$E$51,"=P32",I$12:I$51) -> 0 | J65: =SUMIF($E$12:$E$51,"=P32",J$12:J$51) -> 0 | L65: =SUMIF($E$12:$E$51,"=P32",L$12:L$51) -> 0 | M65: =SUMIF($E$12:$E$51,"=P32",M$12:M$51) -> 0 | N65: =SUMIF($E$12:$E$51,"=P32",N$12:N$51) -> 0 | O65: =SUM(I65:N65) -> 0
...

Sheet Mileage Detail
A1: MILEAGE DETAIL
A2: NAME: | B2: ='Expense Claim Form '!C4 -> Brian Fleming
A4: Date of journey | B4: Details of journey: start, finish and intermediate points; purpose of journey; and any other relevant facts. | C4: Start point postcode | D4: Destination point postcode | E4: Total number of miles travelled | F4: Passenger names | G4: Number of passengers | H4: Total number of passenger miles travelled | I4: Passenger mileage rate (£) | J4: Total passenger miles claimed (£) | L4: FUEL TYPE | M4: DIESEL
B5: NB If the journey begins and ends at the same location (eg your local office), please enter the destination postcode. Please use separate rows if the journey consisted of several legs. | L5: ENGINE CC | M5: 1600
I6: =0.05*G6 -> 0 | J6: =I6*H6 -> 0 | K6: =IF(H6<>0,IF(F6<>0,0,"Error - passenger names need to be input"),0) -> 0 | L6: REG NO. | M6: SB65 XCW
I7: =0.05*G7 -> 0 | J7: =I7*H7 -> 0 | K7: =IF(H7<>0,IF(F7<>0,0,"Error - passenger names need to be input"),0) -> 0 | L7: MAKE | M7: CITREON
I8: =0.05*G8 -> 0 | J8: =I8*H8 -> 0 | K8: =IF(H8<>0,IF(F8<>0,0,"Error - passenger names need to be input"),0) -> 0
I9: =0.05*G9 -> 0 | J9: =I9*H9 -> 0 | K9: =IF(H9<>0,IF(F9<>0,0,"Error - passenger names need to be input"),0) -> 0
I10: =0.05*G10 -> 0 | J10: =I10*H10 -> 0 | K10: =IF(H10<>0,IF(F10<>0,0,"Error - passenger names need to be input"),0) -> 0
I11: =0.05*G11 -> 0 | J11: =I11*H11 -> 0 | K11: =IF(H11<>0,IF(F11<>0,0,"Error - passenger names need to be input"),0) -> 0
I12: =0.05*G12 -> 0 | J12: =I12*H12 -> 0 | K12: =IF(H12<>0,IF(F12<>0,0,"Error - passenger names need to be input"),0) -> 0
I13: =0.05*G13 -> 0 | J13: =I13*H13 -> 0 | K13: =IF(H13<>0,IF(F13<>0,0,"Error - passenger names need to be input"),0) -> 0
I14: =0.05*G14 -> 0 | J14: =I14*H14 -> 0 | K14: =IF(H14<>0,IF(F14<>0,0,"Error - passenger names need to be input"),0) -> 0
I15: =0.05*G15 -> 0 | J15: =I15*H15 -> 0 | K15: =IF(H15<>0,IF(F15<>0,0,"Error - passenger names need to be input"),0) -> 0
I16: =0.05*G16 -> 0 | J16: =I16*H16 -> 0 | K16: =IF(H16<>0,IF(F16<>0,0,"Error - passenger names need to be input"),0) -> 0
I17: =0.05*G17 -> 0 | J17: =I17*H17 -> 0 | K17: =IF(H17<>0,IF(F17<>0,0,"Error - passenger names need to be input"),0) -> 0
I18: =0.05*G18 -> 0 | J18: =I18*H18 -> 0 | K18: =IF(H18<>0,IF(F18<>0,0,"Error - passenger names need to be input"),0) -> 0
I19: =0.05*G19 -> 0 | J19: =I19*H19 -> 0 | K19: =IF(H19<>0,IF(F19<>0,0,"Error - passenger names need to be input"),0) -> 0
... I35: =0.05*G35 -> 0 | J35: =I35*H35 -> 0 | K35: =IF(H35<>0,IF(F35<>0,0,"Error - passenger names need to be input"),0) -> 0
B36: Brought forward from Extra Rows sheet | E36: ='Mileage Detail Extra Rows'!E36 -> 0 | H36: ='Mileage Detail Extra Rows'!H36 -> 0 | J36: ='Mileage Detail Extra Rows'!J36 -> 0
B37: Total miles claimed | E37: =SUM(E6:E36) -> 0 | H37: =SUM(H6:H36) -> 0 | J37: =SUM(J6:J36) -> 0 | K37: =SUM(K6:K36) -> 0

Sheet Mileage Detail Extra Rows
A1: MILEAGE DETAIL
A2: NAME: | B2: ='Mileage Detail'!B2 -> Brian Fleming
A4: Date of journey | B4: Details of journey: start, finish and intermediate points; purpose of journey; and any other relevant facts. | C4: Start point postcode | D4: Destination point postcode | E4: Total number of miles travelled | F4: Passenger names | G4: Number of passengers | H4: Total number of passenger miles travelled | I4: Passenger mileage rate (£) | J4: Total passenger miles claimed (£) | L4: FUEL TYPE | M4: DIESEL
B5: NB If the journey begins and ends at the same location (eg your local office), please enter the destination postcode. Please use separate rows if the journey consisted of several legs. | L5: ENGINE CC | M5: 1600
I6: =0.05*G6 -> 0 | J6: =I6*H6 -> 0 | K6: =IF(H6<>0,IF(F6<>0,0,"Error - passenger names need to be input"),0) -> 0 | L6: REG NO. | M6: SB65 XCW
I7: =0.05*G7 -> 0 | J7: =I7*H7 -> 0 | K7: =IF(H7<>0,IF(F7<>0,0,"Error - passenger names need to be input"),0) -> 0 | L7: MAKE | M7: CITREON
I8: =0.05*G8 -> 0 | J8: =I8*H8 -> 0 | K8: =IF(H8<>0,IF(F8<>0,0,"Error - passenger names need to be input"),0) -> 0
E9: 0 | I9: =0.05*G9 -> 0 | J9: =I9*H9 -> 0 | K9: =IF(H9<>0,IF(F9<>0,0,"Error - passenger names need to be input"),0) -> 0
I10: =0.05*G10 -> 0 | J10: =I10*H10 -> 0 | K10: =IF(H10<>0,IF(F10<>0,0,"Error - passenger names need to be input"),0) -> 0
I11: =0.05*G11 -> 0 | J11: =I11*H11 -> 0 | K11: =IF(H11<>0,IF(F11<>0,0,"Error - passenger names need to be input"),0) -> 0
I12: =0.05*G12 -> 0 | J12: =I12*H12 -> 0 | K12: =IF(H12<>0,IF(F12<>0,0,"Error - passenger names need to be input"),0) -> 0
I13: =0.05*G13 -> 0 | J13: =I13*H13 -> 0 | K13: =IF(H13<>0,IF(F13<>0,0,"Error - passenger names need to be input"),0) -> 0
I14: =0.05*G14 -> 0 | J14: =I14*H14 -> 0 | K14: =IF(H14<>0,IF(F14<>0,0,"Error - passenger names need to be input"),0) -> 0
I15: =0.05*G15 -> 0 | J15: =I15*H15 -> 0 | K15: =IF(H15<>0,IF(F15<>0,0,"Error - passenger names need to be input"),0) -> 0
I16: =0.05*G16 -> 0 | J16: =I16*H16 -> 0 | K16: =IF(H16<>0,IF(F16<>0,0,"Error - passenger names need to be input"),0) -> 0
I17: =0.05*G17 -> 0 | J17: =I17*H17 -> 0 | K17: =IF(H17<>0,IF(F17<>0,0,"Error - passenger names need to be input"),0) -> 0
I18: =0.05*G18 -> 0 | J18: =I18*H18 -> 0 | K18: =IF(H18<>0,IF(F18<>0,0,"Error - passenger names need to be input"),0) -> 0
I19: =0.05*G19 -> 0 | J19: =I19*H19 -> 0 | K19: =IF(H19<>0,IF(F19<>0,0,"Error - passenger names need to be input"),0) -> 0
I20: =0.05*G20 -> 0 | J20: =I20*H20 -> 0 | K20: =IF(H20<>0,IF(F20<>0,0,"Error - passenger names need to be input"),0) -> 0
I21: =0.05*G21 -> 0 | J21: =I21*H21 -> 0 | K21: =IF(H21<>0,IF(F21<>0,0,"Error - passenger names need to be input"),0) -> 0
... I35: =0.05*G35 -> 0 | J35: =I35*H35 -> 0 | K35: =IF(H35<>0,IF(F35<>0,0,"Error - passenger names need to be input"),0) -> 0
B36: Total miles claimed | E36: =SUM(E6:E35) -> 0 | H36: =SUM(H6:H35) -> 0 | J36: =SUM(J6:J35) -> 0 | K36: =SUM(K6:K35) -> 0

Sheet Instructions OLD
A1: Electronic Expenses Claim Form Instructions
A3: The HR Section of InHouse contains the company expenses policy, and can be accessed via the following link (below):
B4: https://taylorwimpey.sharepoint.com/Functions/hr/pages/home.aspx
A6: Expense claims should be made monthly in line with the timetable provided by your local Business Unit Finance Department. Reimbursement will be by BACS or cheque payment. Payments will be delayed if the expense claim form is submitted late. Any expense claim form submitted more than 3 months after the expenses were incurred will be rejected unless there are exceptional and extenuating circumstances to justify the delay. Please bear in mind that delayed expense claims result in significant extra work for processing staff.
A8: The attached claim form should be completed as follows:
A10: Expense Claim Form
A12: 1 | B12: Personal Details
B13: On the main form enter your name, staff number, business unit and department/site.
B14: If you are using the 'Expense Claim Form Extra Rows' tab, this information will feed through automatically.
B15: If claiming mileage, you will need to complete the 'Mileage Detail' tab. Your fuel type, engine size and car registration number will feed through automatically to the main Expense Claim Form from the 'Mileage Detail' tab.
A17: 2 | B17: Date
B18: Please include the date on which the expenditure was incurred.
A20: 3 | B20: Expense Code
B21: An expense code must be entered for the form to automatically populate the relevant columns. The expense codes are as follows (see point 3 for explanation on VAT code):
A23: 3.1 | B23: S = Subsistence
B24: This should be used for all hotel bills and meal costs incurred by TW employees (see also staff entertaining).
B25: Where the expenditure is subject to VAT at the standard rate, VAT code P10 should be used. Please check your invoice/receipt for any zero rated/exempt items such as newspapers or tips/service charges. These expenses should be shown on separate lines and VAT code P01/P30 should be used. If you do not have a VAT receipt/invoice, VAT code P30 should be used.
A27: 3.2 | B27: T = Travel
B28: This should be used for flights, train tickets, tube tickets, bus fares, taxis, M6 toll fees, bridge crossings, car parking and fuel (but not for car rental).
B29: VAT code P01 should be used for flights, train tickets, tube tickets and bus fares.
B30: VAT code P30 should be used for taxis, unless the taxi company is VAT registered and you are issued with a VAT receipt. In this case, VAT code P10 should be used.
B31: VAT code P10 should be used for M6 toll fees. Where VAT is chargeable on a bridge crossing, VAT code P10 should be used. Where the bridge crossing is exempt from VAT, VAT code P30 should be used. If you do not have a VAT receipt, VAT code P30 should be used.
B32: VAT code P10 should be used for car parking where the car parking ticket includes a valid VAT registration number. Where no car parking ticket is issued or it does not contain a valid VAT registration number, VAT code P30 should be used.
B33: VAT code P10 should be used for fuel claims. If you do not have a VAT receipt, VAT code P30 should be used.
B35: All mileage claims should also be coded as 'T'. The VAT code for mileage is dependent on whether or not the claimant has a company car or car allowance:
B37: ■ Company car users and car allowance holders should use VAT code P10.
B38: ■ Staff claiming mileage who neither have a company car nor are in receipt of a car allowance should use VAT code P99 or P98.
B39: ■ It is unlikely that a claimant will have P10, P99 and P98 mileage claims in the same claim period. However, should this occur (eg your status changes and a company car/car allowance is allocated to you), a separate form should be used for each section of the claim.
B41: The number of miles claimed for each trip must be entered on the "Mileage Detail" tab to enable the P98 and P99 VAT calculation.
B43: For those staff who have neither a company car nor a car allowance all mileage claimed up to 10,000, during any tax year, must be claimed at the higher rate of 45p per mile and all mileage exceeding 10,000, during the same tax year, must be claimed at the lower rate of 25p per mile.
B45: Please note that car rental should not be coded as 'T' but as 'O'. VAT code P10 should be used for car rental. If you do not have a valid VAT receipt, VAT code P30 should be used.
A47: 3.3 | B47: E = Business Entertaining
B48: This should be used for events which include non-TW employees. The names and company of non-TW employees should be included on the expense claim form, as should the purpose of the entertaining. Prior authorisation should be obtained for use of this code. VAT code P61 should be used for business entertaining.
A50: 3.4 | B50: ES = Staff Entertaining
B51: This should be used for events held for TW employees. Claims should include the names of the employees attending and the reason for the event. Prior authorisation should be obtained for use of this code. VAT code P10 should be used. If you do not have a valid VAT receipt, VAT code P30 should be used. NB A sandwich lunch to enable a meeting to continue is not staff entertaining. If the sandwich lunch is for a training course or a meeting for TW employees only, the expense should be treated as subsistence. If the meeting includes both TW employees and non-TW employees, the expense should be treated as business entertaining.
A53: 3.5 | B53: PF = Professional Subscriptions
B54: This code should be used to reclaim professional subscriptions (eg CIOB, CIMA, etc). VAT code P10/P01 should be used. If you do not have a valid VAT receipt, VAT code P30 should be used.
A56: 3.6 | B56: O = Other Expenses
B57: This covers all other expenditure (eg car hire, car valeting/cleaning, gifts, team building events, clothing, equipment, office supplies, etc). Where expenses claimed relate to a a gift is claimed please include details of the recipient (employee/non-employee) and a detailed description of the gift.
B58: The majority of these expenses will be subject to VAT at the standard rate and VAT code P10 should be used. Please check your receipt/invoice as the expenses may be a zero-rated or exempt supply. VAT code P01 should be used for zero-rated supplies and VAT code P30 should be used for exempt supplies. IIf you do not have a valid VAT receipt/invoice VAT code P30 should be used.
...

Sheet Mileage Claim Guide OLD
A1: Mileage Claim Guide
B3: The HR Section of InHouse contains the mileage claim policy, and can be accessed via the following link (below):
B4: https://taylorwimpey.sharepoint.com/Functions/hr/pages/home.aspx
A6: Introduction
B7: From time to time employees will, as part of their duties, be required to travel from their usual place of work to another office or location. An employee is permitted to make a mileage claim in respect of the business miles travelled. The mileage rate claimed is dependent on whether or not the employee is in receipt of a company car/car allowance. The mileage rate to be claimed should be entered in the relevant box on the Expense Claim Form.
B9: In exceptional circumstances, and where prior authorisation has been obtained, some employees are able to make a mileage claim in respect of their home to work travel. The mileage rate claimed is dependent on whether or not the employee is in receipt of a company car/car allowance. The mileage rate to be claimed should be entered in the relevant box on the Expense Claim Form.
B11: An employee in receipt of a company car or car allowance is reimbursed at the HMRC advisory rates, which are subject to change from time to time. The current rate can be found by clicking on the link below:
B12: http://www.hmrc.gov.uk/cars/advisory_fuel_current.htm
B14: Other employees are reimbursed at the HMRC authorised rate of 45p per mile for the first 10,000 miles travelled in any one tax year and 25p per mile thereafter.
B16: TW is able to recover the VAT element of mileage claims paid to employees but to sufficient VAT receipts must be attached to the expense claim form to cover the VATable element the claim.
B18: Examples
B19: Advisory Rate - to be completed
B20: An employee makes a claim for 100 miles at 45p per mile, of which 12.5p per mile relates to fuel, 2.5p per mile relates to the VAT on the fuel and 30p relates to the wear and tear of the vehicle. The employee's claim is for £45, but they will only need to provide £12 worth of fuel receipts to enable TW to reclaim the VAT.
B21: An employee makes a claim for 100 miles at 25p per mile, of which 12.5p per mile relates to fuel, 2.5p per mile relates to the VAT on the fuel and 10p relates to the wear and tear of the vehicle. The employee's claim is for £25, but they will still need to provide £12 worth of fuel receipts to enable TW to reclaim the VAT.
A23: Passenger Mileage Rate
B24: Where an employee makes a business journey, and has a passenger (who is also a TW employee), they may claim an additional 5p per mile per passenger. This is known as the passenger mileage rate.
B26: In order to claim the passenger mileage rate the employee must have a genuine business reason for having a passenger (eg attending a training course away from their normal place of work, where the payment of the passenger mileage rate represents a cost-saving to the Business Unit). The passenger mileage rate is not payable in respect of an employee's commute to their normal place of work. The passsenger must be a TW employee and not a contractor/business contact.

Sheet Help

Sheet Module1
